<?xml version="1.0"?>
<robot name="cube">
    <link name="link_0">
        <inertial>
            <origin xyz="0 0 0" rpy="0 0 0"/>
            <mass value="0.37"/>
            <inertia
                ixx="0.00081"
                ixy="0"
                ixz="0"
                iyy="0.00081"
                iyz="0"
                izz="0.00081"/>
        </inertial>
        <visual>
            <origin xyz="0 0 0" rpy="0 0 0" />
            <geometry>
                <box size="0.1048 0.1048 0.1048"/>
            </geometry>
            <material name="pennred">
                <color rgba="0.6 0 0 1.0" />
            </material>
        </visual>
        <collision>
            <geometry>
                <box size="0.1048 0.1048 0.1048"/>
            </geometry>
            <origin xyz="0 0 0" rpy="0 0 0" />
        </collision>
    </link>
    
    <link name="link_1">
    
        <inertial>
            <origin xyz="0 0 0" rpy="0 0 0"/>
            <mass value="0.37"/>
            <inertia
                ixx="0.00081"
                ixy="0"
                ixz="0"
                iyy="0.00081"
                iyz="0"
                izz="0.00081"/>
        </inertial>
        <visual>
            <origin xyz="0 0 0" rpy="0 0 0" />
            <geometry>
                <box size="0.1048 0.1048 0.1048"/>
            </geometry>
            <material name="pennred">
                <color rgba="0.6 0 0 1.0" />
            </material>
        </visual>
        <collision>
            <geometry>
                <box size="0.1048 0.1048 0.1048"/>
            </geometry>
            <origin xyz="0 0 0" rpy="0 0 0" />
        </collision>
    </link>
    <joint name="shaft_0" type="continuous">
    <parent link="link_0"/>
    <child link="link_1"/>
    <origin xyz="-1 1.0 1" rpy="0 0 0"/>
    <axis xyz="0 0 1"/>
    <dynamics damping="0.1"/>
    </joint>
    
    <link name="link_2">
    
        <inertial>
            <origin xyz="0 0 0" rpy="0 0 0"/>
            <mass value="0.37"/>
            <inertia
                ixx="0.00081"
                ixy="0"
                ixz="0"
                iyy="0.00081"
                iyz="0"
                izz="0.00081"/>
        </inertial>
        <visual>
            <origin xyz="0 0 0" rpy="0 0 0" />
            <geometry>
                <box size="0.1048 0.1048 0.1048"/>
            </geometry>
            <material name="pennred">
                <color rgba="0.6 0 0 1.0" />
            </material>
        </visual>
        <collision>
            <geometry>
                <box size="0.1048 0.1048 0.1048"/>
            </geometry>
            <origin xyz="0 0 0" rpy="0 0 0" />
        </collision>
    </link>
    <joint name="shaft_1" type="continuous">
    <parent link="link_1"/>
    <child link="link_2"/>
    <origin xyz="1 1.0 1" rpy="0 0 0"/>
    <axis xyz="0 1 0"/>
    <dynamics damping="0.1"/>
    </joint>
    
</robot>